<?xml version="1.0" encoding="UTF-8"?>
<testng-results ignored="0" total="1" passed="0" failed="1" skipped="0">
  <reporter-output>
  </reporter-output>
  <suite started-at="2022-05-12T18:17:20Z" name="Default suite" finished-at="2022-05-12T18:18:39Z" duration-ms="79052">
    <groups>
    </groups>
    <test started-at="2022-05-12T18:17:20Z" name="Default test" finished-at="2022-05-12T18:18:39Z" duration-ms="79052">
      <class name="tests.NewTest">
        <test-method is-config="true" signature="setup()[pri:0, instance:tests.NewTest@16b2bb0c]" started-at="2022-05-12T18:17:20Z" name="setup" finished-at="2022-05-12T18:17:27Z" duration-ms="6590" status="PASS">
          <reporter-output>
          </reporter-output>
        </test-method> <!-- setup -->
        <test-method signature="f()[pri:0, instance:tests.NewTest@16b2bb0c]" started-at="2022-05-12T18:17:27Z" name="f" finished-at="2022-05-12T18:18:39Z" duration-ms="71718" status="FAIL">
          <exception class="java.lang.AssertionError">
            <message>
              <![CDATA[Sum of prices in cart does not match with Subtotal price expected [€54.26] but found [€154.26]]]>
            </message>
            <full-stacktrace>
              <![CDATA[java.lang.AssertionError: Sum of prices in cart does not match with Subtotal price expected [€54.26] but found [€154.26]
at org.testng.Assert.fail(Assert.java:96)
at org.testng.Assert.failNotEquals(Assert.java:776)
at org.testng.Assert.assertEqualsImpl(Assert.java:137)
at org.testng.Assert.assertEquals(Assert.java:118)
at org.testng.Assert.assertEquals(Assert.java:453)
at tests.NewTest.f(NewTest.java:92)
at java.base/jdk.internal.reflect.NativeMethodAccessorImpl.invoke0(Native Method)
at java.base/jdk.internal.reflect.NativeMethodAccessorImpl.invoke(NativeMethodAccessorImpl.java:62)
at java.base/jdk.internal.reflect.DelegatingMethodAccessorImpl.invoke(DelegatingMethodAccessorImpl.java:43)
at java.base/java.lang.reflect.Method.invoke(Method.java:566)
at org.testng.internal.MethodInvocationHelper.invokeMethod(MethodInvocationHelper.java:124)
at org.testng.internal.Invoker.invokeMethod(Invoker.java:583)
at org.testng.internal.Invoker.invokeTestMethod(Invoker.java:719)
at org.testng.internal.Invoker.invokeTestMethods(Invoker.java:989)
at org.testng.internal.TestMethodWorker.invokeTestMethods(TestMethodWorker.java:125)
at org.testng.internal.TestMethodWorker.run(TestMethodWorker.java:109)
at org.testng.TestRunner.privateRun(TestRunner.java:648)
at org.testng.TestRunner.run(TestRunner.java:505)
at org.testng.SuiteRunner.runTest(SuiteRunner.java:455)
at org.testng.SuiteRunner.runSequentially(SuiteRunner.java:450)
at org.testng.SuiteRunner.privateRun(SuiteRunner.java:415)
at org.testng.SuiteRunner.run(SuiteRunner.java:364)
at org.testng.SuiteRunnerWorker.runSuite(SuiteRunnerWorker.java:52)
at org.testng.SuiteRunnerWorker.run(SuiteRunnerWorker.java:84)
at org.testng.TestNG.runSuitesSequentially(TestNG.java:1208)
at org.testng.TestNG.runSuitesLocally(TestNG.java:1137)
at org.testng.TestNG.runSuites(TestNG.java:1049)
at org.testng.TestNG.run(TestNG.java:1017)
at org.testng.remote.AbstractRemoteTestNG.run(AbstractRemoteTestNG.java:115)
at org.testng.remote.RemoteTestNG.initAndRun(RemoteTestNG.java:251)
at org.testng.remote.RemoteTestNG.main(RemoteTestNG.java:77)
]]>
            </full-stacktrace>
          </exception> <!-- java.lang.AssertionError -->
          <reporter-output>
          </reporter-output>
        </test-method> <!-- f -->
        <test-method is-config="true" signature="teardown()[pri:0, instance:tests.NewTest@16b2bb0c]" started-at="2022-05-12T18:18:39Z" name="teardown" finished-at="2022-05-12T18:18:39Z" duration-ms="717" status="PASS">
          <reporter-output>
          </reporter-output>
        </test-method> <!-- teardown -->
      </class> <!-- tests.NewTest -->
    </test> <!-- Default test -->
  </suite> <!-- Default suite -->
</testng-results>
